<?xml version="1.0" ?>
<robot name="camel_wire_arm">
  <material name="black">
    <color rgba="0.0 0.0 0.0 1.0"/>
  </material>

  <material name="light_gray">
     <color rgba="0.75 0.75 0.75 1.0"/>
  </material>

  <material name="black1">
      <color rgba="0.25 0.25 0.25 0.90"/>
  </material>

  <material name="black2">
      <color rgba="0.35 0.35 0.35 0.90"/>
  </material>

  <link name="world"/>

  <joint name="fixed" type="fixed">
    <parent link="world"/>
    <child link="lower_arm"/>
  </joint>

  <link name="lower_arm">
    <visual>
      <origin rpy="1.570796 0 3.141592" xyz="0.2811 0 0.0474"/>
      <geometry>
        <mesh filename="upper_arm.stl" scale="0.001 0.001 0.001"/>
      </geometry>
      <material name="black1"/>
    </visual>

    <inertial>
      <mass value="0.295"/>
      <inertia ixx="0.0" ixy="0.0" ixz="0.0" iyy="0.00507" iyz="0.0" izz="0.00507"/>
    </inertial>
  </link>

  <joint name="elbow_pitch" type="revolute">
    <origin rpy="1.570796 0 0" xyz="0.2811 0 0.0474"/>
    <parent link="lower_arm"/>
    <child link="upper_arm"/>
    <axis xyz="0 1 0"/>
  </joint>

  <link name="upper_arm">
    <visual>
      <origin rpy="0 0 0" xyz="0 0 0"/>
      <geometry>
        <mesh filename="fore_arm.stl" scale="0.001 0.001 0.001"/>
      </geometry>
      <material name="black1"/>
    </visual>

    <collision>
      <origin rpy="0 0 0" xyz="0.1138 0 0"/>
      <geometry>
        <box size="0.2276 0.07775 0.090"/>
      </geometry>
    </collision>

    <inertial>
      <mass value="0.295"/>
      <inertia ixx="0.0" ixy="0.0" ixz="0.0" iyy="0.00507" iyz="0.0" izz="0.00507"/>
    </inertial>
  </link>
  
</robot>