<?xml version="1.0" encoding="utf-8"?>
<!-- This URDF was automatically created by SolidWorks to URDF Exporter! Originally created by Stephen Brawner (brawner@gmail.com) 
     Commit Version: 1.6.0-4-g7f85cfe  Build Version: 1.6.7995.38578
     For more information, please see http://wiki.ros.org/sw_urdf_exporter -->
<robot
  name="camel_single_leg">
  <link name="world"/>
    <joint name="fixed" type="fixed">
      <parent link="world"/>
      <child link="base"/>
    </joint>

    <link name="base">
      <visual>
        <origin rpy="0 0 0" xyz="0 0 0.5"/>
        <geometry>
          <box size="0.025 0.025 1.0"/>
        </geometry>
        <material name="black"/>
      </visual>

      <collision>
          <origin rpy="0 0 0" xyz="0 0 0.5"/>
        <geometry>
          <box size="0.025 0.025 1.0"/>
        </geometry>
      </collision>

      <inertial>
        <mass value="10"/>
        <inertia ixx="1.0" ixy="0.0" ixz="0.0" iyy="1.0" iyz="0.0" izz="1.0"/>
      </inertial>
    </link>

    <joint name="linear_guide" type="prismatic">
      <origin rpy="0 0 0" xyz="0 -0.025 0.7"/>
      <parent link="base"/>
      <child link="base_link"/>
      <axis xyz="0 0 1"/>
    </joint>
  <link name="base_link">
    <inertial>
      <origin
        xyz="-0.0423754444358588 -0.00139066202933595 0.122407749460709"
        rpy="0 0 -1.5708" />
      <mass
        value="0.287340136606727" />
      <inertia
        ixx="0.000317828389970184"
        ixy="-3.6820786825751E-07"
        ixz="-7.98494336230883E-14"
        iyy="0.000199716903284656"
        iyz="4.87032210354195E-14"
        izz="0.000199238378820781" />
    </inertial>
    <visual>
      <origin
        xyz="0 0 0"
        rpy="0 0 0" />
      <geometry>
        <mesh
          filename="base_link.STL" />
      </geometry>
      <material
        name="">
        <color
          rgba="0.792156862745098 0.819607843137255 0.933333333333333 1" />
      </material>
    </visual>
  </link>
  <link name="link_1">
    <inertial>
      <origin
        xyz="-0.00990673658527552 0.0256760685447313 0.0279283581806484"
        rpy="0 0 0" />
      <mass
        value="0.630895618079" />
      <inertia
        ixx="0.00143812724305677"
        ixy="-9.62502309246475E-07"
        ixz="0.000413569268084497"
        iyy="0.00186571594930576"
        iyz="1.08014383850238E-05"
        izz="0.000520328410132811" />
    </inertial>
    <visual>
      <origin
        xyz="0 0 0"
        rpy="0 0 0" />
      <geometry>
        <mesh
          filename="link_1.STL" />
      </geometry>
      <material
        name="">
        <color
          rgba="0.792156862745098 0.819607843137255 0.933333333333333 1" />
      </material>
    </visual>
  </link>
  <joint
    name="lf_1"
    type="revolute">
    <origin
      xyz="0 -0.12241 -0.001328"
      rpy="-3.1416 -0.23593 1.5708" />
    <parent
      link="base_link" />
    <child
      link="link_1" />
    <axis
      xyz="0 1 0" />
    <limit
      lower="0"
      upper="0"
      effort="0"
      velocity="0" />
  </joint>
  <link
    name="link_2">
    <inertial>
      <origin
        xyz="-0.0480740937956356 -0.0135293612243207 0.116193488898711"
        rpy="0 0 0" />
      <mass
        value="0.081456706464867" />
      <inertia
        ixx="0.000246073484675349"
        ixy="5.97513997768236E-07"
        ixz="9.92043987763118E-05"
        iyy="0.000291331254728072"
        iyz="-1.42904990693618E-06"
        izz="4.77534151893377E-05" />
    </inertial>
    <visual>
      <origin
        xyz="0 0 0"
        rpy="0 0 0" />
      <geometry>
        <mesh
          filename="link_2.STL" />
      </geometry>
      <material
        name="">
        <colors
          rgba="0.792156862745098 0.819607843137255 0.933333333333333 1" />
      </material>
    </visual>
  </link>
  <joint
    name="lf_2"
    type="revolute">
    <origin
      xyz="-0.089994 0.035895 0.21145"
      rpy="-3.1416 1.5088 0" />
    <parent
      link="link_1" />
    <child
      link="link_2" />
    <axis
      xyz="0 1 0" />
    <limit
      lower="0"
      upper="0"
      effort="0"
      velocity="0" />
  </joint>
</robot>